<?xml version="1.0"?>
<robot name="single_joint_arm">

  <!-- Base (fixed) -->
  <link name="base_link">
    <inertial>
      <origin xyz="0 0 0"/>
      <mass value="1.0"/>
      <inertia
        ixx="0.01" ixy="0" ixz="0"
        iyy="0.01" iyz="0"
        izz="0.01"/>
    </inertial>

    <visual>
      <geometry>
        <box size="0.2 0.2 0.05"/>
      </geometry>
      <material name="gray"/>
    </visual>

    <collision>
      <geometry>
        <box size="0.2 0.2 0.05"/>
      </geometry>
    </collision>
  </link>

  <!-- Moving link -->
  <link name="link_1">
    <inertial>
      <origin xyz="0 0 0.15"/>
      <mass value="0.5"/>
      <inertia
        ixx="0.005" ixy="0" ixz="0"
        iyy="0.005" iyz="0"
        izz="0.005"/>
    </inertial>

    <visual>
      <geometry>
        <box size="0.05 0.05 0.3"/>
      </geometry>
      <origin xyz="0 0 0.15"/>
      <material name="blue"/>
    </visual>

    <collision>
      <geometry>
        <box size="0.05 0.05 0.3"/>
      </geometry>
      <origin xyz="0 0 0.15"/>
    </collision>
  </link>

  <!-- Revolute joint -->
  <joint name="joint_1" type="revolute">
    <parent link="base_link"/>
    <child link="link_1"/>
    <origin xyz="0 0 0.025"/>
    <axis xyz="0 1 0"/>
    <limit lower="-1.5" upper="1.5" effort="5" velocity="2.0"/>
  </joint>

</robot>
